#### 一、throw-try-catch基础



##### 如果 if 后面直接加 throw，没有try-catch，则一定只能调用自定义的或系统异常类！

##### 如 ` throw std::runtime_error("out of memory"); `



##### 1、先看个例子：

```cpp
string str = "abcdefghijklmnopq";

try {
    char ch1 = str[10000];
    cout << ch1 << endl;
} 
catch (exception e) {
    cout << "[1]out of bound!" << endl;
}


try {
    char ch2 = str.at(100);
    cout << ch2 << endl;
} 
catch (exception e) {  //exception类位于<exception>头文件中
    cout << "[2]out of bound!" << endl;
}


//看似好像是抛出了两个异常，事实上只有第二个有反应
//结果：[2]out of bound!
```
分析：

> ​	可以看出，第一个 try 没有捕获到异常，什么也没有输出。因为`[]`不会检查下
>
> 标越界，不会抛出异常，所以即使有错误，try 也检测不到。换句话说，发生异常
>
> 时必须将异常明确地抛出，try 才能检测到；如果不抛出来，即使有异常 try 也检
>
> 测不到。所谓抛出异常，就是明确地告诉程序发生了什么错误。
>
> ​	第二个 try 检测到了异常，并交给 catch 处理，执行 catch 中的语句。需要说明
>
> 的是，异常一旦抛出，会立刻被 try 检测到，并且不会再执行异常点（异常发生位
>
> 置）后面的语句。本例中抛出异常的位置是第 13 行的 at() 函数，它后面的 cout 
>
> 语句就不会再被执行，所以看不到它的输出。



因此异常的处理流程：

> 抛出（Throw）--> 检测（Try） --> 捕获（Catch）



##### 2、try块中直接抛出异常

```cpp
#include <iostream>
#include <string>
#include <exception>
using namespace std;

int main(){
    try{
        throw "lalala";  //抛出异常
        cout<<"This statement will not be executed."<<endl;
    }
    catch(const char* &e){
        cout<<e<<endl;
        cout<<"a Exception"<<endl;
    }
    
    return 0;
}


//结果：lalala，成功抛出异常

```

> `throw`关键字用来抛出一个异常，这个异常会被 try 检测到，进而被 catch 捕获。



##### 3、try块中，调用的函数中抛出了异常

```cpp
#include <iostream>
#include <string>
#include <exception>
using namespace std;

void func(){
    throw "Unknown Exception";  //抛出异常
    cout<<"[1]This statement will not be executed."<<endl;
}

int main(){
    try{
        func();
        cout<<"[2]This statement will not be executed."<<endl;
    }
    catch(const char* &e){
        cout<<e<<endl;
    }
    return 0;
}

//结果：Unknown Exception
```

> func函数在try块中被调用，它抛出的异常能被try检测到，进而被catch捕获





#### 二、异常类型

```c
try{
    // 可能抛出异常的语句，如throw等
}catch(exceptionType variable){
    // 处理异常的语句
}
```

> 只有跟 exceptionType **类型匹配的异常数据**才会被传递给 variable；
>
> 否则 catch 不会接收这份异常数据，也不会执行 catch 块中的语句。
>
> c++规定，异常类型可以是 int、char、float、bool 等基本类型，也可以是指针、数组、字符串、结构体、类等聚合类型。C++ 语言本身以及标准库中的函数抛出的异常，都是 exception 类或其子类的异常。也就是说，抛出异常时，会创建一个 exception 类或其子类的对象。

```cpp
int a = 100;

try{
    throw a;
}
catch(const int e){
    cout<<e<<endl;
}

//结果：100
// e用const int修饰，在catch中，创建了一个int的Exception类
```



注意：错误示范

```cpp
char str[] = "nice";

throw str;  

/* 结果：terminate called after throwing an instance of 'char*'
catch中异常并没有匹配上去，
C++的析构函数抛出异常将自动调用terminate()终止程序；
异常能正确抛出的标志：catch里面应该输出的内容，并不是终端反馈的错误！
```



#### 三、自定义异常类 

经典异常类的实现：Out Of Range

在catch捕获的时候，可以模仿Exception：类引用 + 形参方式捕获异常对象

```cpp
//自定义的异常类型
class OutOfRange{
public:
    OutOfRange(): m_flag(1){ };
    OutOfRange(int len, int index): m_len(len), m_index(index), m_flag(2){ }
public:
    void what() const;  //获取具体的错误信息
private:
    int m_flag;  //不同的flag表示不同的错误
    int m_len;  //当前数组的长度
    int m_index;  //当前使用的数组下标
};


void OutOfRange::what() const {
    if(m_flag == 1){
        cout<<"Error: empty array, no elements to pop."<<endl;
    }else if(m_flag == 2){
        cout<<"Error: out of range( array length "<<m_len<<", access index "					<<m_index<<" )"<<endl;
    }else{
        cout<<"Unknown exception."<<endl;
    }
}


//实现动态数组
class Array{
public:
    Array();
    ~Array(){ free(m_p); };
public:
    int operator[](int i) const;  //获取数组元素
    int push(int ele);  //在末尾插入数组元素
    int pop();  //在末尾删除数组元素
    int length() const{ return m_len; };  //获取数组长度
private:
    int m_len;  //数组长度
    int m_capacity;  //当前的内存能容纳多少个元素
    int *m_p;  //内存指针
private:
    static const int m_stepSize = 50;  //每次扩容的步长
};


Array::Array(){
    m_p = (int*)malloc( sizeof(int) * m_stepSize );
    m_capacity = m_stepSize;
    m_len = 0;
}

int Array::operator[](int index) const {
    if( index<0 || index>=m_len ){  //判断是否越界
        throw OutOfRange(m_len, index);  //抛出异常（创建一个匿名对象）
    }
    return *(m_p + index);
}

int Array::push(int ele){
    if(m_len >= m_capacity){  //如果容量不足就扩容
        m_capacity += m_stepSize;
        m_p = (int*)realloc( m_p, sizeof(int) * m_capacity );  //扩容
    }
    *(m_p + m_len) = ele;
    m_len++;
    return m_len-1;
}

int Array::pop(){
    if(m_len == 0){
        throw OutOfRange();  //抛出异常（创建一个匿名对象）
    }
    m_len--;
    return *(m_p + m_len);
}

//打印数组元素
void printArray(Array &arr){
    int len = arr.length();
    //判断数组是否为空
    if(len == 0){
        cout<<"Empty array! No elements to print."<<endl;
        return;
    }
    for(int i=0; i<len; i++){
        if(i == len-1){
            cout<<arr[i]<<endl;
        }else{
            cout<<arr[i]<<", ";
        }
    }
}



int main(){
    Array nums;
    //向数组中添加十个元素
    for(int i=0; i<10; i++){
        nums.push(i);
    }
    printArray(nums);
    
    //尝试访问第20个元素：第一个异常点
    try{
        cout<<nums[20]<<endl;
    }
    catch(OutOfRange &e){
        e.what();
    }
    
    //尝试弹出20个元素：第二个异常点
    try{
        for(int i=0; i<20; i++){
            nums.pop();
        }
    }
    catch(OutOfRange &e){
        e.what();
    }
    
    return 0;
}
```

**分析：**

> Out of Range是自定义的一个异常类；
>
> pop()和operator()中抛出了异常类
>
> operator()中的抛出异常类：
>     if( index<0 || index>=m_len ){ 			 	   //判断是否越界
>         throw OutOfRange(m_len, index); 	 	//抛出异常（有参构造函数：定义处flag = 2）
>     }
>
> 
>
> pop()中的抛出异常类：
>     if(m_len == 0){
>         throw OutOfRange(); 							 //抛出异常（无参构造函数：定义处flag = 1）
>     }
>
>  
>
> 在main里面，就可以利用Exception方式（类引用 + 形参）捕获异常：
>
> catch(OutOfRange &e){
>         e.what();
>  }
>
> 根据flag的值就可以确定抛出的是哪个异常！

```c
/* 结果：
0, 1, 2, 3, 4, 5, 6, 7, 8, 9
Error: out of range( array length 10, access index 20 )
Error: empty array, no elements to pop.
```



​	